Workbook
Name Slicer_Category: #N/A
Name Slicer_Department: #N/A
Name Slicer_Month: #N/A
Name Slicer_Quarter: #N/A
Name Slicer_Region: #N/A
Name Slicer_Sub_Category: #N/A
Name Slicer_Year: #N/A

Sheet Raw_Data
A1: Transaction ID | B1: Date | C1: Month | D1: Quarter | E1: Year | F1: Region | G1: Country | H1: State | I1: City | J1: Branch | K1: Department | L1: Cost Center | M1: Product ID | N1: Product Name | O1: Category | P1: Sub Category | Q1: Revenue | R1: Budget Revenue | S1: COGS | T1: Operating Expense | U1: Marketing Expense | V1: Salary Expense | W1: Misc Expense | X1: Total Expense | Y1: Gross Profit | Z1: Net Profit | AA1: Profit Margin % | AB1: Budget Variance | AC1: Discount | AD1: Tax | AE1: Net Revenue
A2: TXN-00001 | B2: 45850 | C2: July | D2: Q3 | E2: 2025 | F2: West | G2: India | H2: Goa | I2: Vasco da Gama | J2: Branch D | K2: Operations | L2: CC-1002 | M2: P019 | N2: Conference Camera | O2: Electronics | P2: Video Conferencing | Q2: 23278.76 | R2: 22815.81 | S2: 11971.99 | T2: 2376.09 | U2: 667.33 | V2: 2275.73 | W2: 997.48 | X2: 18288.61 | Y2: 11306.77 | Z2: -6981.84 | AA2: -0.2542 | AB2: 462.95 | AC2: 0 | AD2: 4190.18 | AE2: 27468.94
A3: TXN-00002 | B3: 45908 | C3: September | D3: Q3 | E3: 2025 | F3: South | G3: India | H3: Tamil Nadu | I3: Chennai | J3: Branch D | K3: Sales | L3: CC-1003 | M3: P010 | N3: Mouse | O3: Accessories | P3: Computer Accessories | Q3: 2086.76 | R3: 1982.07 | S3: 1047.02 | T3: 207.57 | U3: 104.05 | V3: 247.61 | W3: 54.96 | X3: 1661.21 | Y3: 1039.74 | Z3: -621.47 | AA3: -0.2743 | AB3: 104.69 | AC3: 166.94 | AD3: 345.57 | AE3: 2265.39
A4: TXN-00003 | B4: 46076 | C4: February | D4: Q1 | E4: 2026 | F4: North | G4: India | H4: Uttar Pradesh | I4: Lucknow | J4: Branch D | K4: Operations | L4: CC-1002 | M4: P009 | N4: Keyboard | O4: Accessories | P4: Computer Accessories | Q4: 1176.9 | R4: 1120.77 | S4: 757.9 | T4: 116.28 | U4: 93.16 | V4: 63.4 | W4: 27.88 | X4: 1058.62 | Y4: 419 | Z4: -639.62 | AA4: -0.47 | AB4: 56.13 | AC4: 23.54 | AD4: 207.6 | AE4: 1360.97
A5: TXN-00004 | B5: 45801 | C5: May | D5: Q2 | E5: 2025 | F5: East | G5: India | H5: Odisha | I5: Bhubaneswar | J5: Branch C | K5: Marketing | L5: CC-1004 | M5: P002 | N5: Monitor | O5: Electronics | P5: Computing | Q5: 47762.94 | R5: 52452.38 | S5: 26669.38 | T5: 4567.83 | U5: 2811.05 | V5: 5583.19 | W5: 1889.44 | X5: 41520.9 | Y5: 21093.56 | Z5: -20427.34 | AA5: -0.402 | AB5: -4689.44 | AC5: 2388.15 | AD5: 5444.98 | AE5: 50819.77
A6: TXN-00005 | B6: 46027 | C6: January | D6: Q1 | E6: 2026 | F6: South | G6: India | H6: Kerala | I6: Kochi | J6: Branch A | K6: Sales | L6: CC-1005 | M6: P001 | N6: Business Laptop | O6: Electronics | P6: Computing | Q6: 18810.62 | R6: 18781.73 | S6: 10354.06 | T6: 961.72 | U6: 713.39 | V6: 1822.89 | W6: 708.34 | X6: 14560.39 | Y6: 8456.55 | Z6: -6103.84 | AA6: -0.2895 | AB6: 28.88 | AC6: 940.53 | AD6: 3216.62 | AE6: 21086.7
A7: TXN-00006 | B7: 45788 | C7: May | D7: Q2 | E7: 2025 | F7: Central | G7: India | H7: Madhya Pradesh | I7: Indore | J7: Branch A | K7: Sales | L7: CC-1005 | M7: P003 | N7: Printer | O7: Electronics | P7: Office Equipment | Q7: 41891.12 | R7: 43917.52 | S7: 23957.63 | T7: 5351.04 | U7: 3358.8 | V7: 4094.37 | W7: 764.91 | X7: 37526.76 | Y7: 17933.48 | Z7: -19593.28 | AA7: -0.4545 | AB7: -2026.4 | AC7: 837.82 | AD7: 2052.66 | AE7: 43105.96
A8: TXN-00007 | B8: 45954 | C8: October | D8: Q4 | E8: 2025 | F8: East | G8: India | H8: Odisha | I8: Bhubaneswar | J8: Branch C | K8: Sales | L8: CC-1001 | M8: P020 | N8: Document Scanner | O8: Electronics | P8: Office Equipment | Q8: 51914.87 | R8: 47855.1 | S8: 32449.92 | T8: 4837.81 | U8: 1983.1 | V8: 5992.44 | W8: 1607.3 | X8: 46870.57 | Y8: 19464.95 | Z8: -27405.61 | AA8: -0.4709 | AB8: 4059.77 | AC8: 2595.74 | AD8: 8877.44 | AE8: 58196.57
A9: TXN-00008 | B9: 45917 | C9: September | D9: Q3 | E9: 2025 | F9: West | G9: India | H9: Maharashtra | I9: Mumbai | J9: Branch B | K9: Finance | L9: CC-1004 | M9: P012 | N9: Accounting Software | O9: Software | P9: Business Software | Q9: 18661.59 | R9: 18238.04 | S9: 9504.37 | T9: 1465.01 | U9: 1566.53 | V9: 1152.74 | W9: 609.66 | X9: 14298.29 | Y9: 9157.22 | Z9: -5141.07 | AA9: -0.246 | AB9: 423.55 | AC9: 0 | AD9: 2239.39 | AE9: 20900.98
A10: TXN-00009 | B10: 46006 | C10: December | D10: Q4 | E10: 2025 | F10: North | G10: India | H10: Uttar Pradesh | I10: Agra | J10: Branch A | K10: Finance | L10: CC-1001 | M10: P019 | N10: Conference Camera | O10: Electronics | P10: Video Conferencing | Q10: 27488.07 | R10: 25577.3 | S10: 14637.49 | T10: 2601.69 | U10: 1408.75 | V10: 1242.22 | W10: 519.17 | X10: 20409.32 | Y10: 12850.58 | Z10: -7558.74 | AA10: -0.2378 | AB10: 1910.77 | AC10: 549.76 | AD10: 4848.89 | AE10: 31787.2
A11: TXN-00010 | B11: 45860 | C11: July | D11: Q3 | E11: 2025 | F11: North | G11: India | H11: Uttar Pradesh | I11: Lucknow | J11: Branch C | K11: Operations | L11: CC-1002 | M11: P005 | N11: Office Desk | O11: Furniture | P11: Office Furniture | Q11: 17627.99 | R11: 19112.48 | S11: 10707.67 | T11: 1512.88 | U11: 1074.22 | V11: 1540.96 | W11: 226.16 | X11: 15061.9 | Y11: 6920.32 | Z11: -8141.58 | AA11: -0.4535 | AB11: -1484.48 | AC11: 528.84 | AD11: 854.96 | AE11: 17954.11
A12: TXN-00011 | B12: 46041 | C12: January | D12: Q1 | E12: 2026 | F12: South | G12: India | H12: Kerala | I12: Thiruvananthapuram | J12: Branch B | K12: Finance | L12: CC-1001 | M12: P009 | N12: Keyboard | O12: Accessories | P12: Computer Accessories | Q12: 3190.87 | R12: 2847 | S12: 1984.13 | T12: 332.5 | U12: 83.21 | V12: 258.36 | W12: 57.2 | X12: 2715.4 | Y12: 1206.74 | Z12: -1508.66 | AA12: -0.474 | AB12: 343.87 | AC12: 159.54 | AD12: 151.57 | AE12: 3182.89
A13: TXN-00012 | B13: 45875 | C13: August | D13: Q3 | E13: 2025 | F13: East | G13: India | H13: Jharkhand | I13: Ranchi | J13: Branch C | K13: Sales | L13: CC-1001 | M13: P018 | N13: Projector | O13: Electronics | P13: Presentation | Q13: 78448.53 | R13: 75105.25 | S13: 50081.24 | T13: 9051.22 | U13: 4792.27 | V13: 6461.97 | W13: 1448.54 | X13: 71835.23 | Y13: 28367.29 | Z13: -43467.94 | AA13: -0.4696 | AB13: 3343.28 | AC13: 0 | AD13: 14120.74 | AE13: 92569.27
... A206: TXN-00205 | B206: 45776 | C206: April | D206: Q2 | E206: 2025 | F206: West | G206: India | H206: Rajasthan | I206: Jodhpur | J206: Branch D | K206: IT | L206: CC-1004 | M206: P009 | N206: Keyboard | O206: Accessories | P206: Computer Accessories | Q206: 6731.64 | R206: 7582.63 | S206: 4593.66 | T206: 597.82 | U206: 314.27 | V206: 695.54 | W206: 173.64 | X206: 6374.94 | Y206: 2137.98 | Z206: -4236.96 | AA206: -0.5443 | AB206: -850.99 | AC206: 134.63 | AD206: 1187.46 | AE206: 7784.46
A207: TXN-00206 | B207: 46018 | C207: December | D207: Q4 | E207: 2025 | F207: East | G207: India | H207: West Bengal | J207: Branch B | K207: Operations | L207: CC-1002 | M207: P019 | N207: Conference Camera | O207: Electronics | P207: Video Conferencing | Q207: 27294.21 | R207: 24362.7 | S207: 16240.67 | T207: 1761.51 | U207: 2000.67 | V207: 2943.25 | W207: 794.14 | X207: 23740.24 | Y207: 11053.54 | Z207: -12686.7 | AA207: -0.4611 | AB207: 2931.52 | AC207: 2729.42 | AD207: 2947.78 | AE207: 27512.57
A208: TXN-00207 | B208: 46080 | C208: February | D208: Q1 | E208: 2026 | F208: West | G208: India | H208: Goa | I208: Panaji | J208: Branch C | K208: Sales | L208: CC-1003 | M208: P019 | N208: Conference Camera | O208: Electronics | P208: Video Conferencing | Q208: 25282.94 | R208: 26863.7 | S208: 16423.6 | T208: 2021.58 | U208: 1239.28 | V208: 1102.98 | W208: 562.5 | X208: 21349.94 | Y208: 8859.34 | Z208: -12490.6 | AA208: -0.4795 | AB208: -1580.76 | AC208: 2022.64 | AD208: 2791.24 | AE208: 26051.54
A209: TXN-00208 | B209: 45809 | C209: June | D209: Q2 | E209: 2025 | F209: West | G209: India | H209: Maharashtra | I209: Nagpur | J209: Branch D | K209: Sales | L209: CC-1001 | M209: P004 | N209: Office Chair | O209: Furniture | P209: Office Furniture | Q209: 27355.34 | R209: 30489.93 | S209: 18065.99 | T209: 3125.08 | U209: 1604.95 | V209: 1401.3 | W209: 916.14 | X209: 25113.47 | Y209: 9289.35 | Z209: -15824.12 | AA209: -0.516 | AB209: -3134.59 | AC209: 1367.77 | AD209: 4677.76 | AE209: 30665.33
A210: TXN-00209 | B210: 45818 | C210: June | D210: Q2 | E210: 2025 | F210: West | G210: India | H210: Goa | I210: Margao | J210: Branch A | K210: Sales | L210: CC-1003 | M210: P004 | N210: Office Chair | O210: Furniture | P210: Office Furniture | Q210: 28763.31 | R210: 31854.79 | S210: 15925.01 | T210: 2393.04 | U210: 2051.7 | V210: 2039.23 | W210: 880.09 | X210: 23289.08 | Y210: 12838.3 | Z210: -10450.78 | AA210: -0.331 | AB210: -3091.49 | AC210: 575.27 | AD210: 3382.57 | AE210: 31570.61
A211: TXN-00210 | B211: 45841 | C211: July | D211: Q3 | E211: 2025 | F211: Central | G211: India | H211: Chhattisgarh | I211: Bilaspur | J211: Branch C | K211: Operations | L211: CC-1002 | M211: P002 | N211: Monitor | O211: Electronics | P211: Computing | Q211: 24677.74 | R211: 25053.66 | S211: 17522.17 | T211: 2084.95 | U211: 1498.12 | V211: 2039.87 | W211: 796.76 | X211: 23941.87 | Y211: 7155.57 | Z211: -16786.29 | AA211: -0.6819 | AB211: -375.91 | AC211: 1233.89 | AD211: 1172.19 | AE211: 24616.05
A212: TXN-00211 | B212: 45920 | C212: September | D212: Q3 | E212: 2025 | F212: West | G212: India | H212: Maharashtra | I212: Pune | J212: Branch B | K212: Sales | L212: CC-1004 | M212: P007 | N212: Tablet | O212: Electronics | P212: Mobile | Q212: 34917.73 | R212: 39264.36 | S212: 23280.56 | T212: 3871.26 | U212: 1299.01 | V212: 1643.61 | W212: 1203.38 | X212: 31297.81 | Y212: 11637.17 | Z212: -19660.64 | AA212: -0.5183 | AB212: -4346.63 | AC212: 1047.53 | AD212: 4064.42 | AE212: 37934.62
A213: TXN-00212 | B213: 46004 | C213: December | D213: Q4 | E213: 2025 | F213: East | G213: India | H213: Odisha | I213: Cuttack | J213: Branch A | K213: Marketing | L213: CC-1003 | M213: P015 | N213: Network Router | O213: Networking | P213: Network Equipment | Q213: 17482.77 | R213: 18882.34 | S213: 9747.11 | T213: 2129.99 | U213: 1446.31 | V213: 1154.27 | W213: 726.12 | X213: 15203.8 | Y213: 7735.66 | Z213: -7468.14 | AA213: -0.4022 | AB213: -1399.57 | AC213: 1748.28 | AD213: 2832.21 | AE213: 18566.7
A214: TXN-00213 | B214: 46005 | C214: December | D214: Q4 | E214: 2025 | F214: West | G214: India | H214: Maharashtra | I214: Pune | J214: Branch A | K214: Sales | L214: CC-1003 | M214: P020 | N214: Document Scanner | O214: Electronics | P214: Office Equipment | Q214: 79192.1 | R214: 88727.18 | S214: 50827.24 | T214: 3995.83 | U214: 4377.63 | V214: 6786.21 | W214: 1634.61 | X214: 67621.53 | Y214: 28364.86 | Z214: -39256.67 | AA214: -0.4287 | AB214: -9535.08 | AC214: 1583.84 | AD214: 13969.49 | AE214: 91577.75
A215: TXN-00214 | B215: 45934 | C215: October | D215: Q4 | E215: 2025 | F215: West | G215: India | H215: Gujarat | I215: Vadodara | J215: Branch B | K215: Sales | L215: CC-1005 | M215: P003 | N215: Printer | O215: Electronics | P215: Office Equipment | Q215: 14247.77 | R215: 16455.9 | S215: 9253.61 | T215: 1064.54 | U215: 479.04 | V215: 1153.08 | W215: 145.14 | X215: 12095.42 | Y215: 4994.16 | Z215: -7101.27 | AA215: -0.4945 | AB215: -2208.13 | AC215: 1424.78 | AD215: 1538.76 | AE215: 14361.75
A216: TXN-00215 | B216: 45872 | C216: August | D216: Q3 | E216: 2025 | F216: West | G216: India | H216: Maharashtra | I216: Mumbai | J216: Branch A | K216: Marketing | L216: CC-1003 | M216: P002 | N216: Monitor | O216: Electronics | P216: Computing | Q216: 50404.03 | R216: 47816.42 | S216: 31414.03 | T216: 6262.93 | U216: 4304.21 | V216: 3394.83 | W216: 1434.94 | X216: 46810.94 | Y216: 18990 | Z216: -27820.94 | AA216: -0.4773 | AB216: 2587.61 | AC216: 1008.08 | AD216: 8891.27 | AE216: 58287.23
A217: TXN-00216 | B217: 46015 | C217: December | D217: Q4 | E217: 2025 | F217: East | G217: India | H217: Odisha | I217: Bhubaneswar | J217: Branch B | K217: Marketing | L217: CC-1001 | M217: P014 | N217: Data Storage | O217: Software | P217: Cloud Services | Q217: 6369.34 | R217: 6894.41 | S217: 4092.99 | T217: 508.59 | U217: 549.1 | V217: 340.05 | W217: 175.24 | X217: 5665.97 | Y217: 2276.36 | Z217: -3389.61 | AA217: -0.4747 | AB217: -525.06 | AC217: 318.47 | AD217: 1089.16 | AE217: 7140.04
A218: TXN-00217 | B218: 45929 | C218: September | D218: Q3 | E218: 2025 | F218: South | G218: India | H218: Telangana | I218: Hyderabad | J218: Branch D | K218: Marketing | L218: CC-1001 | M218: P015 | N218: Network Router | O218: Networking | P218: Network Equipment | Q218: 9860.57 | R218: 10392.23 | S218: 5804.9 | T218: 1241.44 | U218: 285.36 | V218: 935.09 | W218: 107.22 | X218: 8374.02 | Y218: 4055.67 | Z218: -4318.35 | AA218: -0.391 | AB218: -531.66 | AC218: 0 | AD218: 1183.27 | AE218: 11043.84
A219: TXN-00218 | B219: 46043 | C219: January | D219: Q1 | E219: 2026 | F219: West | G219: India | H219: Gujarat | I219: Surat | J219: Branch C | K219: Operations | L219: CC-1002 | M219: P013 | N219: CRM Software | O219: Software | P219: Business Software | Q219: 9333.46 | R219: 8989.09 | S219: 6543.81 | T219: 902.13 | U219: 593 | V219: 638.35 | W219: 110.32 | X219: 8787.61 | Y219: 2789.64 | Z219: -5997.97 | AA219: -0.5738 | AB219: 344.37 | AC219: 0 | AD219: 1120.01 | AE219: 10453.47
... A1001: TXN-01000 | B1001: 46000 | C1001: December | D1001: Q4 | E1001: 2025 | F1001: West | G1001: India | H1001: Maharashtra | I1001: Nagpur | J1001: Branch A | K1001: Finance | L1001: CC-1003 | M1001: P016 | N1001: Network Switch | O1001: Networking | P1001: Network Equipment | Q1001: 34733.42 | R1001: 30619.73 | S1001: 24454.69 | T1001: 3158 | U1001: 2450.36 | V1001: 3766.84 | W1001: 915.18 | X1001: 34745.07 | Y1001: 10278.73 | Z1001: -24466.34 | AA1001: -0.7292 | AB1001: 4113.7 | AC1001: 2778.67 | AD1001: 1597.74 | AE1001: 33552.49

Sheet Data Cleaning
A1: Transaction ID | B1: Date | C1: Month | D1: Quarter | E1: Year | F1: Region | G1: Country | H1: State | I1: City | J1: Branch | K1: Department | L1: Cost Center | M1: Product ID | N1: Product Name | O1: Category | P1: Sub Category | Q1: Revenue | R1: Budget Revenue | S1: COGS | T1: Operating Expense | U1: Marketing Expense | V1: Salary Expense | W1: Misc Expense | X1: Total Expense | Y1: Gross Profit | Z1: Net Profit | AA1: Profit Margin % | AB1: Budget Variance | AC1: Discount | AD1: Tax | AE1: Net Revenue | AF1: Clean City | AG1: Clean State | AH1: Clean Department | AI1: Clean Product Name | AJ1: Clean Cost Center | AL1: DATA QUALITY CHECKS
A2: TXN-00001 | B2: 45850 | C2: July | D2: ="Q"&INT(MOD(MONTH(B2)-4,12)/3)+1 -> Q2 | E2: ="FY"& (YEAR(B2)+(MONTH(B2)>=4)) -> FY2026 | F2: West | G2: India | H2: Goa | I2: Vasco da Gama | J2: Branch D | K2: Operations | L2: CC-1002 | M2: P019 | N2: Conference Camera | O2: Electronics | P2: Video Conferencing | Q2: 23278.76 | R2: 22815.81 | S2: 11971.99 | T2: 2376.09 | U2: 667.33 | V2: 2275.73 | W2: 997.48 | X2: 18288.61 | Y2: 11306.77 | Z2: =Q2-X2 -> 4990.15 | AA2: =Z2/Q2 -> 0.21436494 | AB2: 462.95 | AC2: 0 | AD2: 4190.18 | AE2: 27468.94 | AF2: =IF(tbl_FinancialData[[#This Row],[City]]="","Unknown",PROPER(TRIM(tbl_FinancialData[[#This Row],[City]]))) -> Vasco Da Gama | AG2: =_xlfn.LET(_xlpm.city,LOWER(TRIM(tbl_FinancialData[[#This Row],[City]])),_xlpm.st,PROPER(TRIM(tbl_FinancialData[[#This Row],[State]])),IF(_xlpm.city="pune","Maharashtra",IF(_xlpm.city="jamshedpur","Jharkhand",IF(_xlpm.city="bhilai","Chhattisgarh",IF(_xlpm.city="mumbai","Maharashtra",_xlpm.st))))) -> Goa | AH2: =_xlfn.LET(_xlpm.d,PROPER(TRIM(tbl_FinancialData[[#This Row],[Department]])),IF(_xlpm.d="It","IT",_xlpm.d)) -> Operations | AI2: =_xlfn.LET(_xlpm.pid,tbl_FinancialData[[#This Row],[Product ID]],_xlpm.n,PROPER(TRIM(tbl_FinancialData[[#This Row],[Product Name]])),IF(_xlpm.pid="P020","Document Scanner",IF(_xlpm.pid="P015","Network Router",SUBSTITUTE(SUBSTITUTE(_xlpm.n,"Crm","CRM"),"Ups","UPS")))) -> Conference Camera | AJ2: =UPPER(TRIM(tbl_FinancialData[[#This Row],[Cost Center]])) -> CC-1002
A3: TXN-00002 | B3: 45908 | C3: September | D3: ="Q"&INT(MOD(MONTH(B3)-4,12)/3)+1 -> Q2 | E3: ="FY"& (YEAR(B3)+(MONTH(B3)>=4)) -> FY2026 | F3: South | G3: India | H3: Tamil Nadu | I3: Chennai | J3: Branch D | K3: Sales | L3: CC-1003 | M3: P010 | N3: Mouse | O3: Accessories | P3: Computer Accessories | Q3: 2086.76 | R3: 1982.07 | S3: 1047.02 | T3: 207.57 | U3: 104.05 | V3: 247.61 | W3: 54.96 | X3: 1661.21 | Y3: 1039.74 | Z3: =Q3-X3 -> 425.55 | AA3: =Z3/Q3 -> 0.20392858 | AB3: 104.69 | AC3: 166.94 | AD3: 345.57 | AE3: 2265.39 | AF3: =IF(tbl_FinancialData[[#This Row],[City]]="","Unknown",PROPER(TRIM(tbl_FinancialData[[#This Row],[City]]))) -> Chennai | AG3: =_xlfn.LET(_xlpm.city,LOWER(TRIM(tbl_FinancialData[[#This Row],[City]])),_xlpm.st,PROPER(TRIM(tbl_FinancialData[[#This Row],[State]])),IF(_xlpm.city="pune","Maharashtra",IF(_xlpm.city="jamshedpur","Jharkhand",IF(_xlpm.city="bhilai","Chhattisgarh",IF(_xlpm.city="mumbai","Maharashtra",_xlpm.st))))) -> Tamil Nadu | AH3: =_xlfn.LET(_xlpm.d,PROPER(TRIM(tbl_FinancialData[[#This Row],[Department]])),IF(_xlpm.d="It","IT",_xlpm.d)) -> Sales | AI3: =_xlfn.LET(_xlpm.pid,tbl_FinancialData[[#This Row],[Product ID]],_xlpm.n,PROPER(TRIM(tbl_FinancialData[[#This Row],[Product Name]])),IF(_xlpm.pid="P020","Document Scanner",IF(_xlpm.pid="P015","Network Router",SUBSTITUTE(SUBSTITUTE(_xlpm.n,"Crm","CRM"),"Ups","UPS")))) -> Mouse | AJ3: =UPPER(TRIM(tbl_FinancialData[[#This Row],[Cost Center]])) -> CC-1003 | AL3: Check | AM3: Result | AN3: Status
A4: TXN-00003 | B4: 46076 | C4: February | D4: ="Q"&INT(MOD(MONTH(B4)-4,12)/3)+1 -> Q4 | E4: ="FY"& (YEAR(B4)+(MONTH(B4)>=4)) -> FY2026 | F4: North | G4: India | H4: Uttar Pradesh | I4: Lucknow | J4: Branch D | K4: Operations | L4: CC-1002 | M4: P009 | N4: Keyboard | O4: Accessories | P4: Computer Accessories | Q4: 1176.9 | R4: 1120.77 | S4: 757.9 | T4: 116.28 | U4: 93.16 | V4: 63.4 | W4: 27.88 | X4: 1058.62 | Y4: 419 | Z4: =Q4-X4 -> 118.28 | AA4: =Z4/Q4 -> 0.10050132 | AB4: 56.13 | AC4: 23.54 | AD4: 207.6 | AE4: 1360.97 | AF4: =IF(tbl_FinancialData[[#This Row],[City]]="","Unknown",PROPER(TRIM(tbl_FinancialData[[#This Row],[City]]))) -> Lucknow | AG4: =_xlfn.LET(_xlpm.city,LOWER(TRIM(tbl_FinancialData[[#This Row],[City]])),_xlpm.st,PROPER(TRIM(tbl_FinancialData[[#This Row],[State]])),IF(_xlpm.city="pune","Maharashtra",IF(_xlpm.city="jamshedpur","Jharkhand",IF(_xlpm.city="bhilai","Chhattisgarh",IF(_xlpm.city="mumbai","Maharashtra",_xlpm.st))))) -> Uttar Pradesh | AH4: =_xlfn.LET(_xlpm.d,PROPER(TRIM(tbl_FinancialData[[#This Row],[Department]])),IF(_xlpm.d="It","IT",_xlpm.d)) -> Operations | AI4: =_xlfn.LET(_xlpm.pid,tbl_FinancialData[[#This Row],[Product ID]],_xlpm.n,PROPER(TRIM(tbl_FinancialData[[#This Row],[Product Name]])),IF(_xlpm.pid="P020","Document Scanner",IF(_xlpm.pid="P015","Network Router",SUBSTITUTE(SUBSTITUTE(_xlpm.n,"Crm","CRM"),"Ups","UPS")))) -> Keyboard | AJ4: =UPPER(TRIM(tbl_FinancialData[[#This Row],[Cost Center]])) -> CC-1002 | AL4: Total Records | AM4: =ROWS(tbl_FinancialData[Transaction ID]) -> 1000 | AN4: =IF(AM4=1000,"PASS","CHECK") -> PASS
A5: TXN-00004 | B5: 45801 | C5: May | D5: ="Q"&INT(MOD(MONTH(B5)-4,12)/3)+1 -> Q1 | E5: ="FY"& (YEAR(B5)+(MONTH(B5)>=4)) -> FY2026 | F5: East | G5: India | H5: Odisha | I5: Bhubaneswar | J5: Branch C | K5: Marketing | L5: CC-1004 | M5: P002 | N5: Monitor | O5: Electronics | P5: Computing | Q5: 47762.94 | R5: 52452.38 | S5: 26669.38 | T5: 4567.83 | U5: 2811.05 | V5: 5583.19 | W5: 1889.44 | X5: 41520.9 | Y5: 21093.56 | Z5: =Q5-X5 -> 6242.04 | AA5: =Z5/Q5 -> 0.13068794 | AB5: -4689.44 | AC5: 2388.15 | AD5: 5444.98 | AE5: 50819.77 | AF5: =IF(tbl_FinancialData[[#This Row],[City]]="","Unknown",PROPER(TRIM(tbl_FinancialData[[#This Row],[City]]))) -> Bhubaneswar | AG5: =_xlfn.LET(_xlpm.city,LOWER(TRIM(tbl_FinancialData[[#This Row],[City]])),_xlpm.st,PROPER(TRIM(tbl_FinancialData[[#This Row],[State]])),IF(_xlpm.city="pune","Maharashtra",IF(_xlpm.city="jamshedpur","Jharkhand",IF(_xlpm.city="bhilai","Chhattisgarh",IF(_xlpm.city="mumbai","Maharashtra",_xlpm.st))))) -> Odisha | AH5: =_xlfn.LET(_xlpm.d,PROPER(TRIM(tbl_FinancialData[[#This Row],[Department]])),IF(_xlpm.d="It","IT",_xlpm.d)) -> Marketing | AI5: =_xlfn.LET(_xlpm.pid,tbl_FinancialData[[#This Row],[Product ID]],_xlpm.n,PROPER(TRIM(tbl_FinancialData[[#This Row],[Product Name]])),IF(_xlpm.pid="P020","Document Scanner",IF(_xlpm.pid="P015","Network Router",SUBSTITUTE(SUBSTITUTE(_xlpm.n,"Crm","CRM"),"Ups","UPS")))) -> Monitor | AJ5: =UPPER(TRIM(tbl_FinancialData[[#This Row],[Cost Center]])) -> CC-1004 | AL5: Duplicate Transaction IDs | AM5: =ROWS(tbl_FinancialData[Transaction ID])-ROWS(_xlfn.UNIQUE(tbl_FinancialData[Transaction ID])) -> 0 | AN5: =IF(AM5=0,"PASS","CHECK") -> PASS
A6: TXN-00005 | B6: 46027 | C6: January | D6: ="Q"&INT(MOD(MONTH(B6)-4,12)/3)+1 -> Q4 | E6: ="FY"& (YEAR(B6)+(MONTH(B6)>=4)) -> FY2026 | F6: South | G6: India | H6: Kerala | I6: Kochi | J6: Branch A | K6: Sales | L6: CC-1005 | M6: P001 | N6: Business Laptop | O6: Electronics | P6: Computing | Q6: 18810.62 | R6: 18781.73 | S6: 10354.06 | T6: 961.72 | U6: 713.39 | V6: 1822.89 | W6: 708.34 | X6: 14560.39 | Y6: 8456.55 | Z6: =Q6-X6 -> 4250.23 | AA6: =Z6/Q6 -> 0.22594843 | AB6: 28.88 | AC6: 940.53 | AD6: 3216.62 | AE6: 21086.7 | AF6: =IF(tbl_FinancialData[[#This Row],[City]]="","Unknown",PROPER(TRIM(tbl_FinancialData[[#This Row],[City]]))) -> Kochi | AG6: =_xlfn.LET(_xlpm.city,LOWER(TRIM(tbl_FinancialData[[#This Row],[City]])),_xlpm.st,PROPER(TRIM(tbl_FinancialData[[#This Row],[State]])),IF(_xlpm.city="pune","Maharashtra",IF(_xlpm.city="jamshedpur","Jharkhand",IF(_xlpm.city="bhilai","Chhattisgarh",IF(_xlpm.city="mumbai","Maharashtra",_xlpm.st))))) -> Kerala | AH6: =_xlfn.LET(_xlpm.d,PROPER(TRIM(tbl_FinancialData[[#This Row],[Department]])),IF(_xlpm.d="It","IT",_xlpm.d)) -> Sales | AI6: =_xlfn.LET(_xlpm.pid,tbl_FinancialData[[#This Row],[Product ID]],_xlpm.n,PROPER(TRIM(tbl_FinancialData[[#This Row],[Product Name]])),IF(_xlpm.pid="P020","Document Scanner",IF(_xlpm.pid="P015","Network Router",SUBSTITUTE(SUBSTITUTE(_xlpm.n,"Crm","CRM"),"Ups","UPS")))) -> Business Laptop | AJ6: =UPPER(TRIM(tbl_FinancialData[[#This Row],[Cost Center]])) -> CC-1005 | AL6: Blank Transaction IDs | AM6: =COUNTBLANK(tbl_FinancialData[Transaction ID]) -> 0 | AN6: =IF(AM6=0,"PASS","CHECK") -> PASS
A7: TXN-00006 | B7: 45788 | C7: May | D7: ="Q"&INT(MOD(MONTH(B7)-4,12)/3)+1 -> Q1 | E7: ="FY"& (YEAR(B7)+(MONTH(B7)>=4)) -> FY2026 | F7: Central | G7: India | H7: Madhya Pradesh | I7: Indore | J7: Branch A | K7: Sales | L7: CC-1005 | M7: P003 | N7: Printer | O7: Electronics | P7: Office Equipment | Q7: 41891.12 | R7: 43917.52 | S7: 23957.63 | T7: 5351.04 | U7: 3358.8 | V7: 4094.37 | W7: 764.91 | X7: 37526.76 | Y7: 17933.48 | Z7: =Q7-X7 -> 4364.36 | AA7: =Z7/Q7 -> 0.10418342 | AB7: -2026.4 | AC7: 837.82 | AD7: 2052.66 | AE7: 43105.96 | AF7: =IF(tbl_FinancialData[[#This Row],[City]]="","Unknown",PROPER(TRIM(tbl_FinancialData[[#This Row],[City]]))) -> Indore | AG7: =_xlfn.LET(_xlpm.city,LOWER(TRIM(tbl_FinancialData[[#This Row],[City]])),_xlpm.st,PROPER(TRIM(tbl_FinancialData[[#This Row],[State]])),IF(_xlpm.city="pune","Maharashtra",IF(_xlpm.city="jamshedpur","Jharkhand",IF(_xlpm.city="bhilai","Chhattisgarh",IF(_xlpm.city="mumbai","Maharashtra",_xlpm.st))))) -> Madhya Pradesh | AH7: =_xlfn.LET(_xlpm.d,PROPER(TRIM(tbl_FinancialData[[#This Row],[Department]])),IF(_xlpm.d="It","IT",_xlpm.d)) -> Sales | AI7: =_xlfn.LET(_xlpm.pid,tbl_FinancialData[[#This Row],[Product ID]],_xlpm.n,PROPER(TRIM(tbl_FinancialData[[#This Row],[Product Name]])),IF(_xlpm.pid="P020","Document Scanner",IF(_xlpm.pid="P015","Network Router",SUBSTITUTE(SUBSTITUTE(_xlpm.n,"Crm","CRM"),"Ups","UPS")))) -> Printer | AJ7: =UPPER(TRIM(tbl_FinancialData[[#This Row],[Cost Center]])) -> CC-1005 | AL7: Blank Dates | AM7: =COUNTBLANK(tbl_FinancialData[Date]) -> 0 | AN7: =IF(AM7=0,"PASS","CHECK") -> PASS
A8: TXN-00007 | B8: 45954 | C8: October | D8: ="Q"&INT(MOD(MONTH(B8)-4,12)/3)+1 -> Q3 | E8: ="FY"& (YEAR(B8)+(MONTH(B8)>=4)) -> FY2026 | F8: East | G8: India | H8: Odisha | I8: Bhubaneswar | J8: Branch C | K8: Sales | L8: CC-1001 | M8: P020 | N8: Document Scanner | O8: Electronics | P8: Office Equipment | Q8: 51914.87 | R8: 47855.1 | S8: 32449.92 | T8: 4837.81 | U8: 1983.1 | V8: 5992.44 | W8: 1607.3 | X8: 46870.57 | Y8: 19464.95 | Z8: =Q8-X8 -> 5044.3 | AA8: =Z8/Q8 -> 0.097164839 | AB8: 4059.77 | AC8: 2595.74 | AD8: 8877.44 | AE8: 58196.57 | AF8: =IF(tbl_FinancialData[[#This Row],[City]]="","Unknown",PROPER(TRIM(tbl_FinancialData[[#This Row],[City]]))) -> Bhubaneswar | AG8: =_xlfn.LET(_xlpm.city,LOWER(TRIM(tbl_FinancialData[[#This Row],[City]])),_xlpm.st,PROPER(TRIM(tbl_FinancialData[[#This Row],[State]])),IF(_xlpm.city="pune","Maharashtra",IF(_xlpm.city="jamshedpur","Jharkhand",IF(_xlpm.city="bhilai","Chhattisgarh",IF(_xlpm.city="mumbai","Maharashtra",_xlpm.st))))) -> Odisha | AH8: =_xlfn.LET(_xlpm.d,PROPER(TRIM(tbl_FinancialData[[#This Row],[Department]])),IF(_xlpm.d="It","IT",_xlpm.d)) -> Sales | AI8: =_xlfn.LET(_xlpm.pid,tbl_FinancialData[[#This Row],[Product ID]],_xlpm.n,PROPER(TRIM(tbl_FinancialData[[#This Row],[Product Name]])),IF(_xlpm.pid="P020","Document Scanner",IF(_xlpm.pid="P015","Network Router",SUBSTITUTE(SUBSTITUTE(_xlpm.n,"Crm","CRM"),"Ups","UPS")))) -> Document Scanner | AJ8: =UPPER(TRIM(tbl_FinancialData[[#This Row],[Cost Center]])) -> CC-1001 | AL8: Blank Revenue | AM8: =COUNTBLANK(tbl_FinancialData[Revenue]) -> 0 | AN8: =IF(AM8=0,"PASS","CHECK") -> PASS
A9: TXN-00008 | B9: 45917 | C9: September | D9: ="Q"&INT(MOD(MONTH(B9)-4,12)/3)+1 -> Q2 | E9: ="FY"& (YEAR(B9)+(MONTH(B9)>=4)) -> FY2026 | F9: West | G9: India | H9: Maharashtra | I9: Mumbai | J9: Branch B | K9: Finance | L9: CC-1004 | M9: P012 | N9: Accounting Software | O9: Software | P9: Business Software | Q9: 18661.59 | R9: 18238.04 | S9: 9504.37 | T9: 1465.01 | U9: 1566.53 | V9: 1152.74 | W9: 609.66 | X9: 14298.29 | Y9: 9157.22 | Z9: =Q9-X9 -> 4363.3 | AA9: =Z9/Q9 -> 0.2338118 | AB9: 423.55 | AC9: 0 | AD9: 2239.39 | AE9: 20900.98 | AF9: =IF(tbl_FinancialData[[#This Row],[City]]="","Unknown",PROPER(TRIM(tbl_FinancialData[[#This Row],[City]]))) -> Mumbai | AG9: =_xlfn.LET(_xlpm.city,LOWER(TRIM(tbl_FinancialData[[#This Row],[City]])),_xlpm.st,PROPER(TRIM(tbl_FinancialData[[#This Row],[State]])),IF(_xlpm.city="pune","Maharashtra",IF(_xlpm.city="jamshedpur","Jharkhand",IF(_xlpm.city="bhilai","Chhattisgarh",IF(_xlpm.city="mumbai","Maharashtra",_xlpm.st))))) -> Maharashtra | AH9: =_xlfn.LET(_xlpm.d,PROPER(TRIM(tbl_FinancialData[[#This Row],[Department]])),IF(_xlpm.d="It","IT",_xlpm.d)) -> Finance | AI9: =_xlfn.LET(_xlpm.pid,tbl_FinancialData[[#This Row],[Product ID]],_xlpm.n,PROPER(TRIM(tbl_FinancialData[[#This Row],[Product Name]])),IF(_xlpm.pid="P020","Document Scanner",IF(_xlpm.pid="P015","Network Router",SUBSTITUTE(SUBSTITUTE(_xlpm.n,"Crm","CRM"),"Ups","UPS")))) -> Accounting Software | AJ9: =UPPER(TRIM(tbl_FinancialData[[#This Row],[Cost Center]])) -> CC-1004 | AL9: Negative Revenue | AM9: =COUNTIF(tbl_FinancialData[Revenue],"<0") -> 0 | AN9: =IF(AM9=0,"PASS","CHECK") -> PASS
A10: TXN-00009 | B10: 46006 | C10: December | D10: ="Q"&INT(MOD(MONTH(B10)-4,12)/3)+1 -> Q3 | E10: ="FY"& (YEAR(B10)+(MONTH(B10)>=4)) -> FY2026 | F10: North | G10: India | H10: Uttar Pradesh | I10: Agra | J10: Branch A | K10: Finance | L10: CC-1001 | M10: P019 | N10: Conference Camera | O10: Electronics | P10: Video Conferencing | Q10: 27488.07 | R10: 25577.3 | S10: 14637.49 | T10: 2601.69 | U10: 1408.75 | V10: 1242.22 | W10: 519.17 | X10: 20409.32 | Y10: 12850.58 | Z10: =Q10-X10 -> 7078.75 | AA10: =Z10/Q10 -> 0.25752081 | AB10: 1910.77 | AC10: 549.76 | AD10: 4848.89 | AE10: 31787.2 | AF10: =IF(tbl_FinancialData[[#This Row],[City]]="","Unknown",PROPER(TRIM(tbl_FinancialData[[#This Row],[City]]))) -> Agra | AG10: =_xlfn.LET(_xlpm.city,LOWER(TRIM(tbl_FinancialData[[#This Row],[City]])),_xlpm.st,PROPER(TRIM(tbl_FinancialData[[#This Row],[State]])),IF(_xlpm.city="pune","Maharashtra",IF(_xlpm.city="jamshedpur","Jharkhand",IF(_xlpm.city="bhilai","Chhattisgarh",IF(_xlpm.city="mumbai","Maharashtra",_xlpm.st))))) -> Uttar Pradesh | AH10: =_xlfn.LET(_xlpm.d,PROPER(TRIM(tbl_FinancialData[[#This Row],[Department]])),IF(_xlpm.d="It","IT",_xlpm.d)) -> Finance | AI10: =_xlfn.LET(_xlpm.pid,tbl_FinancialData[[#This Row],[Product ID]],_xlpm.n,PROPER(TRIM(tbl_FinancialData[[#This Row],[Product Name]])),IF(_xlpm.pid="P020","Document Scanner",IF(_xlpm.pid="P015","Network Router",SUBSTITUTE(SUBSTITUTE(_xlpm.n,"Crm","CRM"),"Ups","UPS")))) -> Conference Camera | AJ10: =UPPER(TRIM(tbl_FinancialData[[#This Row],[Cost Center]])) -> CC-1001 | AL10: Negative Budget Revenue | AM10: =COUNTIF(tbl_FinancialData[Budget Revenue],"<0") -> 0 | AN10: =IF(AM10=0,"PASS","CHECK") -> PASS
A11: TXN-00010 | B11: 45860 | C11: July | D11: ="Q"&INT(MOD(MONTH(B11)-4,12)/3)+1 -> Q2 | E11: ="FY"& (YEAR(B11)+(MONTH(B11)>=4)) -> FY2026 | F11: North | G11: India | H11: Uttar Pradesh | I11: Lucknow | J11: Branch C | K11: Operations | L11: CC-1002 | M11: P005 | N11: Office Desk | O11: Furniture | P11: Office Furniture | Q11: 17627.99 | R11: 19112.48 | S11: 10707.67 | T11: 1512.88 | U11: 1074.22 | V11: 1540.96 | W11: 226.16 | X11: 15061.9 | Y11: 6920.32 | Z11: =Q11-X11 -> 2566.09 | AA11: =Z11/Q11 -> 0.14556906 | AB11: -1484.48 | AC11: 528.84 | AD11: 854.96 | AE11: 17954.11 | AF11: =IF(tbl_FinancialData[[#This Row],[City]]="","Unknown",PROPER(TRIM(tbl_FinancialData[[#This Row],[City]]))) -> Lucknow | AG11: =_xlfn.LET(_xlpm.city,LOWER(TRIM(tbl_FinancialData[[#This Row],[City]])),_xlpm.st,PROPER(TRIM(tbl_FinancialData[[#This Row],[State]])),IF(_xlpm.city="pune","Maharashtra",IF(_xlpm.city="jamshedpur","Jharkhand",IF(_xlpm.city="bhilai","Chhattisgarh",IF(_xlpm.city="mumbai","Maharashtra",_xlpm.st))))) -> Uttar Pradesh | AH11: =_xlfn.LET(_xlpm.d,PROPER(TRIM(tbl_FinancialData[[#This Row],[Department]])),IF(_xlpm.d="It","IT",_xlpm.d)) -> Operations | AI11: =_xlfn.LET(_xlpm.pid,tbl_FinancialData[[#This Row],[Product ID]],_xlpm.n,PROPER(TRIM(tbl_FinancialData[[#This Row],[Product Name]])),IF(_xlpm.pid="P020","Document Scanner",IF(_xlpm.pid="P015","Network Router",SUBSTITUTE(SUBSTITUTE(_xlpm.n,"Crm","CRM"),"Ups","UPS")))) -> Office Desk | AJ11: =UPPER(TRIM(tbl_FinancialData[[#This Row],[Cost Center]])) -> CC-1002
A12: TXN-00011 | B12: 46041 | C12: January | D12: ="Q"&INT(MOD(MONTH(B12)-4,12)/3)+1 -> Q4 | E12: ="FY"& (YEAR(B12)+(MONTH(B12)>=4)) -> FY2026 | F12: South | G12: India | H12: Kerala | I12: Thiruvananthapuram | J12: Branch B | K12: Finance | L12: CC-1001 | M12: P009 | N12: Keyboard | O12: Accessories | P12: Computer Accessories | Q12: 3190.87 | R12: 2847 | S12: 1984.13 | T12: 332.5 | U12: 83.21 | V12: 258.36 | W12: 57.2 | X12: 2715.4 | Y12: 1206.74 | Z12: =Q12-X12 -> 475.47 | AA12: =Z12/Q12 -> 0.14900952 | AB12: 343.87 | AC12: 159.54 | AD12: 151.57 | AE12: 3182.89 | AF12: =IF(tbl_FinancialData[[#This Row],[City]]="","Unknown",PROPER(TRIM(tbl_FinancialData[[#This Row],[City]]))) -> Thiruvananthapuram | AG12: =_xlfn.LET(_xlpm.city,LOWER(TRIM(tbl_FinancialData[[#This Row],[City]])),_xlpm.st,PROPER(TRIM(tbl_FinancialData[[#This Row],[State]])),IF(_xlpm.city="pune","Maharashtra",IF(_xlpm.city="jamshedpur","Jharkhand",IF(_xlpm.city="bhilai","Chhattisgarh",IF(_xlpm.city="mumbai","Maharashtra",_xlpm.st))))) -> Kerala | AH12: =_xlfn.LET(_xlpm.d,PROPER(TRIM(tbl_FinancialData[[#This Row],[Department]])),IF(_xlpm.d="It","IT",_xlpm.d)) -> Finance | AI12: =_xlfn.LET(_xlpm.pid,tbl_FinancialData[[#This Row],[Product ID]],_xlpm.n,PROPER(TRIM(tbl_FinancialData[[#This Row],[Product Name]])),IF(_xlpm.pid="P020","Document Scanner",IF(_xlpm.pid="P015","Network Router",SUBSTITUTE(SUBSTITUTE(_xlpm.n,"Crm","CRM"),"Ups","UPS")))) -> Keyboard | AJ12: =UPPER(TRIM(tbl_FinancialData[[#This Row],[Cost Center]])) -> CC-1001 | AL12: FINANCIAL VALIDATION
A13: TXN-00012 | B13: 45875 | C13: August | D13: ="Q"&INT(MOD(MONTH(B13)-4,12)/3)+1 -> Q2 | E13: ="FY"& (YEAR(B13)+(MONTH(B13)>=4)) -> FY2026 | F13: East | G13: India | H13: Jharkhand | I13: Ranchi | J13: Branch C | K13: Sales | L13: CC-1001 | M13: P018 | N13: Projector | O13: Electronics | P13: Presentation | Q13: 78448.53 | R13: 75105.25 | S13: 50081.24 | T13: 9051.22 | U13: 4792.27 | V13: 6461.97 | W13: 1448.54 | X13: 71835.23 | Y13: 28367.29 | Z13: =Q13-X13 -> 6613.3 | AA13: =Z13/Q13 -> 0.084301133 | AB13: 3343.28 | AC13: 0 | AD13: 14120.74 | AE13: 92569.27 | AF13: =IF(tbl_FinancialData[[#This Row],[City]]="","Unknown",PROPER(TRIM(tbl_FinancialData[[#This Row],[City]]))) -> Ranchi | AG13: =_xlfn.LET(_xlpm.city,LOWER(TRIM(tbl_FinancialData[[#This Row],[City]])),_xlpm.st,PROPER(TRIM(tbl_FinancialData[[#This Row],[State]])),IF(_xlpm.city="pune","Maharashtra",IF(_xlpm.city="jamshedpur","Jharkhand",IF(_xlpm.city="bhilai","Chhattisgarh",IF(_xlpm.city="mumbai","Maharashtra",_xlpm.st))))) -> Jharkhand | AH13: =_xlfn.LET(_xlpm.d,PROPER(TRIM(tbl_FinancialData[[#This Row],[Department]])),IF(_xlpm.d="It","IT",_xlpm.d)) -> Sales | AI13: =_xlfn.LET(_xlpm.pid,tbl_FinancialData[[#This Row],[Product ID]],_xlpm.n,PROPER(TRIM(tbl_FinancialData[[#This Row],[Product Name]])),IF(_xlpm.pid="P020","Document Scanner",IF(_xlpm.pid="P015","Network Router",SUBSTITUTE(SUBSTITUTE(_xlpm.n,"Crm","CRM"),"Ups","UPS")))) -> Projector | AJ13: =UPPER(TRIM(tbl_FinancialData[[#This Row],[Cost Center]])) -> CC-1001
A14: TXN-00013 | B14: 45784 | C14: May | D14: ="Q"&INT(MOD(MONTH(B14)-4,12)/3)+1 -> Q1 | E14: ="FY"& (YEAR(B14)+(MONTH(B14)>=4)) -> FY2026 | F14: Central | G14: India | H14: Uttar Pradesh | I14: Lucknow | J14: Branch A | K14: Sales | L14: CC-1003 | M14: P020 | N14: Document Scanner | O14: Electronics | P14: Office Equipment | Q14: 72701.69 | R14: 77980.53 | S14: 36364.92 | T14: 4575.14 | U14: 6063.76 | V14: 6435.14 | W14: 750.42 | X14: 54189.38 | Y14: 36336.77 | Z14: =Q14-X14 -> 18512.31 | AA14: =Z14/Q14 -> 0.25463383 | AB14: -5278.83 | AC14: 0 | AD14: 13086.3 | AE14: 85788 | AF14: =IF(tbl_FinancialData[[#This Row],[City]]="","Unknown",PROPER(TRIM(tbl_FinancialData[[#This Row],[City]]))) -> Lucknow | AG14: =_xlfn.LET(_xlpm.city,LOWER(TRIM(tbl_FinancialData[[#This Row],[City]])),_xlpm.st,PROPER(TRIM(tbl_FinancialData[[#This Row],[State]])),IF(_xlpm.city="pune","Maharashtra",IF(_xlpm.city="jamshedpur","Jharkhand",IF(_xlpm.city="bhilai","Chhattisgarh",IF(_xlpm.city="mumbai","Maharashtra",_xlpm.st))))) -> Uttar Pradesh | AH14: =_xlfn.LET(_xlpm.d,PROPER(TRIM(tbl_FinancialData[[#This Row],[Department]])),IF(_xlpm.d="It","IT",_xlpm.d)) -> Sales | AI14: =_xlfn.LET(_xlpm.pid,tbl_FinancialData[[#This Row],[Product ID]],_xlpm.n,PROPER(TRIM(tbl_FinancialData[[#This Row],[Product Name]])),IF(_xlpm.pid="P020","Document Scanner",IF(_xlpm.pid="P015","Network Router",SUBSTITUTE(SUBSTITUTE(_xlpm.n,"Crm","CRM"),"Ups","UPS")))) -> Document Scanner | AJ14: =UPPER(TRIM(tbl_FinancialData[[#This Row],[Cost Center]])) -> CC-1003 | AL14: Validation Check | AM14: Invalid Rows | AN14: Status
A15: TXN-00014 | B15: 46096 | C15: March | D15: ="Q"&INT(MOD(MONTH(B15)-4,12)/3)+1 -> Q4 | E15: ="FY"& (YEAR(B15)+(MONTH(B15)>=4)) -> FY2026 | F15: South | G15: India | H15: Tamil Nadu | I15: Coimbatore | J15: Branch B | K15: Operations | L15: CC-1005 | M15: P009 | N15: Keyboard | O15: Accessories | P15: Computer Accessories | Q15: 1957.06 | R15: 2012.19 | S15: 1023.38 | T15: 155.23 | U15: 143.59 | V15: 191.16 | W15: 40.67 | X15: 1554.03 | Y15: 933.68 | Z15: =Q15-X15 -> 403.03 | AA15: =Z15/Q15 -> 0.20593646 | AB15: -55.13 | AC15: 97.85 | AD15: 223.1 | AE15: 2082.31 | AF15: =IF(tbl_FinancialData[[#This Row],[City]]="","Unknown",PROPER(TRIM(tbl_FinancialData[[#This Row],[City]]))) -> Coimbatore | AG15: =_xlfn.LET(_xlpm.city,LOWER(TRIM(tbl_FinancialData[[#This Row],[City]])),_xlpm.st,PROPER(TRIM(tbl_FinancialData[[#This Row],[State]])),IF(_xlpm.city="pune","Maharashtra",IF(_xlpm.city="jamshedpur","Jharkhand",IF(_xlpm.city="bhilai","Chhattisgarh",IF(_xlpm.city="mumbai","Maharashtra",_xlpm.st))))) -> Tamil Nadu | AH15: =_xlfn.LET(_xlpm.d,PROPER(TRIM(tbl_FinancialData[[#This Row],[Department]])),IF(_xlpm.d="It","IT",_xlpm.d)) -> Operations | AI15: =_xlfn.LET(_xlpm.pid,tbl_FinancialData[[#This Row],[Product ID]],_xlpm.n,PROPER(TRIM(tbl_FinancialData[[#This Row],[Product Name]])),IF(_xlpm.pid="P020","Document Scanner",IF(_xlpm.pid="P015","Network Router",SUBSTITUTE(SUBSTITUTE(_xlpm.n,"Crm","CRM"),"Ups","UPS")))) -> Keyboard | AJ15: =UPPER(TRIM(tbl_FinancialData[[#This Row],[Cost Center]])) -> CC-1005 | AL15: Total Expense Calculation | AM15: {=SUMPRODUCT(--(ABS((tbl_FinancialData[COGS]+tbl_FinancialData[Operating Expense]+tbl_FinancialData[Marketing Expense]+tbl_FinancialData[Salary Expense]+tbl_FinancialData[Misc Expense])-tbl_FinancialData[Total Expense])>0.05))} -> 0 | AN15: =IF(AM15=0,"PASS","CHECK") -> PASS
A16: TXN-00015 | B16: 45769 | C16: April | D16: ="Q"&INT(MOD(MONTH(B16)-4,12)/3)+1 -> Q1 | E16: ="FY"& (YEAR(B16)+(MONTH(B16)>=4)) -> FY2026 | F16: South | G16: India | H16: Tamil Nadu | I16: Coimbatore | J16: Branch A | K16: Finance | L16: CC-1003 | M16: P002 | N16: Monitor | O16: Electronics | P16: Computing | Q16: 39175.98 | R16: 42336.59 | S16: 26929.57 | T16: 2680.22 | U16: 2250.56 | V16: 3359.74 | W16: 1445.57 | X16: 36665.67 | Y16: 12246.4 | Z16: =Q16-X16 -> 2510.31 | AA16: =Z16/Q16 -> 0.064077784 | AB16: -3160.61 | AC16: 0 | AD16: 7051.68 | AE16: 46227.65 | AF16: =IF(tbl_FinancialData[[#This Row],[City]]="","Unknown",PROPER(TRIM(tbl_FinancialData[[#This Row],[City]]))) -> Coimbatore | AG16: =_xlfn.LET(_xlpm.city,LOWER(TRIM(tbl_FinancialData[[#This Row],[City]])),_xlpm.st,PROPER(TRIM(tbl_FinancialData[[#This Row],[State]])),IF(_xlpm.city="pune","Maharashtra",IF(_xlpm.city="jamshedpur","Jharkhand",IF(_xlpm.city="bhilai","Chhattisgarh",IF(_xlpm.city="mumbai","Maharashtra",_xlpm.st))))) -> Tamil Nadu | AH16: =_xlfn.LET(_xlpm.d,PROPER(TRIM(tbl_FinancialData[[#This Row],[Department]])),IF(_xlpm.d="It","IT",_xlpm.d)) -> Finance | AI16: =_xlfn.LET(_xlpm.pid,tbl_FinancialData[[#This Row],[Product ID]],_xlpm.n,PROPER(TRIM(tbl_FinancialData[[#This Row],[Product Name]])),IF(_xlpm.pid="P020","Document Scanner",IF(_xlpm.pid="P015","Network Router",SUBSTITUTE(SUBSTITUTE(_xlpm.n,"Crm","CRM"),"Ups","UPS")))) -> Monitor | AJ16: =UPPER(TRIM(tbl_FinancialData[[#This Row],[Cost Center]])) -> CC-1003 | AL16: Gross Profit Calculation | AM16: {=SUMPRODUCT(--(ABS((tbl_FinancialData[Revenue]-tbl_FinancialData[COGS])-tbl_FinancialData[Gross Profit])>0.05))} -> 0 | AN16: =IF(AM16=0,"PASS","CHECK") -> PASS
A17: TXN-00016 | B17: 45905 | C17: September | D17: ="Q"&INT(MOD(MONTH(B17)-4,12)/3)+1 -> Q2 | E17: ="FY"& (YEAR(B17)+(MONTH(B17)>=4)) -> FY2026 | F17: Central | G17: India | H17: Madhya Pradesh | I17: Indore | J17: Branch C | K17: Marketing | L17: CC-1005 | M17: P017 | N17: UPS System | O17: Electronics | P17: Power Equipment | Q17: 48086.6 | R17: 56458.46 | S17: 23951.12 | T17: 3580.32 | U17: 1798.88 | V17: 2956.27 | W17: 1297.61 | X17: 33584.21 | Y17: 24135.48 | Z17: =Q17-X17 -> 14502.39 | AA17: =Z17/Q17 -> 0.30158901 | AB17: -8371.85 | AC17: 1442.6 | AD17: 5597.28 | AE17: 52241.29 | AF17: =IF(tbl_FinancialData[[#This Row],[City]]="","Unknown",PROPER(TRIM(tbl_FinancialData[[#This Row],[City]]))) -> Indore | AG17: =_xlfn.LET(_xlpm.city,LOWER(TRIM(tbl_FinancialData[[#This Row],[City]])),_xlpm.st,PROPER(TRIM(tbl_FinancialData[[#This Row],[State]])),IF(_xlpm.city="pune","Maharashtra",IF(_xlpm.city="jamshedpur","Jharkhand",IF(_xlpm.city="bhilai","Chhattisgarh",IF(_xlpm.city="mumbai","Maharashtra",_xlpm.st))))) -> Madhya Pradesh | AH17: =_xlfn.LET(_xlpm.d,PROPER(TRIM(tbl_FinancialData[[#This Row],[Department]])),IF(_xlpm.d="It","IT",_xlpm.d)) -> Marketing | AI17: =_xlfn.LET(_xlpm.pid,tbl_FinancialData[[#This Row],[Product ID]],_xlpm.n,PROPER(TRIM(tbl_FinancialData[[#This Row],[Product Name]])),IF(_xlpm.pid="P020","Document Scanner",IF(_xlpm.pid="P015","Network Router",SUBSTITUTE(SUBSTITUTE(_xlpm.n,"Crm","CRM"),"Ups","UPS")))) -> UPS System | AJ17: =UPPER(TRIM(tbl_FinancialData[[#This Row],[Cost Center]])) -> CC-1005 | AL17: Net Profit Calculation | AM17: {=SUMPRODUCT(--(ABS((tbl_FinancialData[Revenue]-tbl_FinancialData[Total Expense])-tbl_FinancialData[Net Profit])>0.05))} -> 0 | AN17: =IF(AM17=0,"PASS","CHECK") -> PASS
A18: TXN-00017 | B18: 45801 | C18: May | D18: ="Q"&INT(MOD(MONTH(B18)-4,12)/3)+1 -> Q1 | E18: ="FY"& (YEAR(B18)+(MONTH(B18)>=4)) -> FY2026 | F18: West | G18: India | H18: Rajasthan | I18: Jodhpur | J18: Branch D | K18: Sales | L18: CC-1002 | M18: P010 | N18: Mouse | O18: Accessories | P18: Computer Accessories | Q18: 9607.66 | R18: 10463.75 | S18: 6231.49 | T18: 756.69 | U18: 423.54 | V18: 1006.39 | W18: 368.49 | X18: 8786.61 | Y18: 3376.17 | Z18: =Q18-X18 -> 821.05 | AA18: =Z18/Q18 -> 0.085457853 | AB18: -856.09 | AC18: 768.61 | AD18: 1591.03 | AE18: 10430.08 | AF18: =IF(tbl_FinancialData[[#This Row],[City]]="","Unknown",PROPER(TRIM(tbl_FinancialData[[#This Row],[City]]))) -> Jodhpur | AG18: =_xlfn.LET(_xlpm.city,LOWER(TRIM(tbl_FinancialData[[#This Row],[City]])),_xlpm.st,PROPER(TRIM(tbl_FinancialData[[#This Row],[State]])),IF(_xlpm.city="pune","Maharashtra",IF(_xlpm.city="jamshedpur","Jharkhand",IF(_xlpm.city="bhilai","Chhattisgarh",IF(_xlpm.city="mumbai","Maharashtra",_xlpm.st))))) -> Rajasthan | AH18: =_xlfn.LET(_xlpm.d,PROPER(TRIM(tbl_FinancialData[[#This Row],[Department]])),IF(_xlpm.d="It","IT",_xlpm.d)) -> Sales | AI18: =_xlfn.LET(_xlpm.pid,tbl_FinancialData[[#This Row],[Product ID]],_xlpm.n,PROPER(TRIM(tbl_FinancialData[[#This Row],[Product Name]])),IF(_xlpm.pid="P020","Document Scanner",IF(_xlpm.pid="P015","Network Router",SUBSTITUTE(SUBSTITUTE(_xlpm.n,"Crm","CRM"),"Ups","UPS")))) -> Mouse | AJ18: =UPPER(TRIM(tbl_FinancialData[[#This Row],[Cost Center]])) -> CC-1002 | AL18: Budget Variance Calculation | AM18: {=SUMPRODUCT(--(ABS((tbl_FinancialData[Revenue]-tbl_FinancialData[Budget Revenue])-tbl_FinancialData[Budget Variance])>0.05))} -> 0 | AN18: =IF(AM18=0,"PASS","CHECK") -> PASS
A19: TXN-00018 | B19: 46060 | C19: February | D19: ="Q"&INT(MOD(MONTH(B19)-4,12)/3)+1 -> Q4 | E19: ="FY"& (YEAR(B19)+(MONTH(B19)>=4)) -> FY2026 | F19: West | G19: India | H19: Rajasthan | I19: pune | J19: Branch D | K19: Marketing | L19: CC-1004 | M19: P019 | N19: Conference Camera | O19: Electronics | P19: Video Conferencing | Q19: 33050.48 | R19: 30016.27 | S19: 20451.22 | T19: 1747.56 | U19: 1826.5 | V19: 2756.79 | W19: 661.97 | X19: 27444.03 | Y19: 12599.27 | Z19: =Q19-X19 -> 5606.45 | AA19: =Z19/Q19 -> 0.16963294 | AB19: 3034.21 | AC19: 1652.52 | AD19: 1569.9 | AE19: 32967.85 | AF19: =IF(tbl_FinancialData[[#This Row],[City]]="","Unknown",PROPER(TRIM(tbl_FinancialData[[#This Row],[City]]))) -> Pune | AG19: =_xlfn.LET(_xlpm.city,LOWER(TRIM(tbl_FinancialData[[#This Row],[City]])),_xlpm.st,PROPER(TRIM(tbl_FinancialData[[#This Row],[State]])),IF(_xlpm.city="pune","Maharashtra",IF(_xlpm.city="jamshedpur","Jharkhand",IF(_xlpm.city="bhilai","Chhattisgarh",IF(_xlpm.city="mumbai","Maharashtra",_xlpm.st))))) -> Maharashtra | AH19: =_xlfn.LET(_xlpm.d,PROPER(TRIM(tbl_FinancialData[[#This Row],[Department]])),IF(_xlpm.d="It","IT",_xlpm.d)) -> Marketing | AI19: =_xlfn.LET(_xlpm.pid,tbl_FinancialData[[#This Row],[Product ID]],_xlpm.n,PROPER(TRIM(tbl_FinancialData[[#This Row],[Product Name]])),IF(_xlpm.pid="P020","Document Scanner",IF(_xlpm.pid="P015","Network Router",SUBSTITUTE(SUBSTITUTE(_xlpm.n,"Crm","CRM"),"Ups","UPS")))) -> Conference Camera | AJ19: =UPPER(TRIM(tbl_FinancialData[[#This Row],[Cost Center]])) -> CC-1004 | AL19: Net Revenue Calculation | AM19: {=SUMPRODUCT(--(ABS((tbl_FinancialData[Revenue]-tbl_FinancialData[Discount]+tbl_FinancialData[Tax])-tbl_FinancialData[Net Revenue])>0.05))} -> 0 | AN19: =IF(AM19=0,"PASS","CHECK") -> PASS
A20: TXN-00019 | B20: 45927 | C20: September | D20: ="Q"&INT(MOD(MONTH(B20)-4,12)/3)+1 -> Q2 | E20: ="FY"& (YEAR(B20)+(MONTH(B20)>=4)) -> FY2026 | F20: North | G20: India | H20: Haryana | I20: Faridabad | J20: Branch C | K20: Sales | L20: CC-1001 | M20: P008 | N20: Headset | O20: Accessories | P20: Audio | Q20: 6337.58 | R20: 6761.36 | S20: 3171.85 | T20: 343.08 | U20: 377.33 | V20: 527.61 | W20: 204.77 | X20: 4624.64 | Y20: 3165.73 | Z20: =Q20-X20 -> 1712.94 | AA20: =Z20/Q20 -> 0.27028298 | AB20: -423.78 | AC20: 316.88 | AD20: 1083.73 | AE20: 7104.43 | AF20: =IF(tbl_FinancialData[[#This Row],[City]]="","Unknown",PROPER(TRIM(tbl_FinancialData[[#This Row],[City]]))) -> Faridabad | AG20: =_xlfn.LET(_xlpm.city,LOWER(TRIM(tbl_FinancialData[[#This Row],[City]])),_xlpm.st,PROPER(TRIM(tbl_FinancialData[[#This Row],[State]])),IF(_xlpm.city="pune","Maharashtra",IF(_xlpm.city="jamshedpur","Jharkhand",IF(_xlpm.city="bhilai","Chhattisgarh",IF(_xlpm.city="mumbai","Maharashtra",_xlpm.st))))) -> Haryana | AH20: =_xlfn.LET(_xlpm.d,PROPER(TRIM(tbl_FinancialData[[#This Row],[Department]])),IF(_xlpm.d="It","IT",_xlpm.d)) -> Sales | AI20: =_xlfn.LET(_xlpm.pid,tbl_FinancialData[[#This Row],[Product ID]],_xlpm.n,PROPER(TRIM(tbl_FinancialData[[#This Row],[Product Name]])),IF(_xlpm.pid="P020","Document Scanner",IF(_xlpm.pid="P015","Network Router",SUBSTITUTE(SUBSTITUTE(_xlpm.n,"Crm","CRM"),"Ups","UPS")))) -> Headset | AJ20: =UPPER(TRIM(tbl_FinancialData[[#This Row],[Cost Center]])) -> CC-1001 | AL20: Profit Margin Calculation | AM20: {=SUMPRODUCT(--(ABS((tbl_FinancialData[Net Profit]/IF(tbl_FinancialData[Revenue]=0,1,tbl_FinancialData[Revenue]))-tbl_FinancialData[Profit Margin %])>0.0001))} -> 0 | AN20: =IF(AM20=0,"PASS","CHECK") -> PASS
A21: TXN-00020 | B21: 45871 | C21: August | D21: ="Q"&INT(MOD(MONTH(B21)-4,12)/3)+1 -> Q2 | E21: ="FY"& (YEAR(B21)+(MONTH(B21)>=4)) -> FY2026 | F21: West | G21: India | H21: Goa | I21: Panaji | J21: Branch D | K21: Sales | L21: CC-1004 | M21: P005 | N21: Office Desk | O21: Furniture | P21: Office Furniture | Q21: 9626.48 | R21: 9708.25 | S21: 6211.39 | T21: 526.14 | U21: 813.33 | V21: 725.72 | W21: 177.06 | X21: 8453.64 | Y21: 3415.09 | Z21: =Q21-X21 -> 1172.84 | AA21: =Z21/Q21 -> 0.12183477 | AB21: -81.77 | AC21: 0 | AD21: 481.32 | AE21: 10107.8 | AF21: =IF(tbl_FinancialData[[#This Row],[City]]="","Unknown",PROPER(TRIM(tbl_FinancialData[[#This Row],[City]]))) -> Panaji | AG21: =_xlfn.LET(_xlpm.city,LOWER(TRIM(tbl_FinancialData[[#This Row],[City]])),_xlpm.st,PROPER(TRIM(tbl_FinancialData[[#This Row],[State]])),IF(_xlpm.city="pune","Maharashtra",IF(_xlpm.city="jamshedpur","Jharkhand",IF(_xlpm.city="bhilai","Chhattisgarh",IF(_xlpm.city="mumbai","Maharashtra",_xlpm.st))))) -> Goa | AH21: =_xlfn.LET(_xlpm.d,PROPER(TRIM(tbl_FinancialData[[#This Row],[Department]])),IF(_xlpm.d="It","IT",_xlpm.d)) -> Sales | AI21: =_xlfn.LET(_xlpm.pid,tbl_FinancialData[[#This Row],[Product ID]],_xlpm.n,PROPER(TRIM(tbl_FinancialData[[#This Row],[Product Name]])),IF(_xlpm.pid="P020","Document Scanner",IF(_xlpm.pid="P015","Network Router",SUBSTITUTE(SUBSTITUTE(_xlpm.n,"Crm","CRM"),"Ups","UPS")))) -> Office Desk | AJ21: =UPPER(TRIM(tbl_FinancialData[[#This Row],[Cost Center]])) -> CC-1004
A22: TXN-00021 | B22: 45984 | C22: November | D22: ="Q"&INT(MOD(MONTH(B22)-4,12)/3)+1 -> Q3 | E22: ="FY"& (YEAR(B22)+(MONTH(B22)>=4)) -> FY2026 | F22: South | G22: India | H22: Kerala | I22: Kochi | J22: Branch C | K22: Operations | L22: CC-1005 | M22: P003 | N22: Printer | O22: Electronics | P22: Office Equipment | Q22: 28563.85 | R22: 31630.29 | S22: 13809.32 | T22: 1693.43 | U22: 799.51 | V22: 1235.62 | W22: 1140.87 | X22: 18678.76 | Y22: 14754.53 | Z22: =Q22-X22 -> 9885.09 | AA22: =Z22/Q22 -> 0.34606995 | AB22: -3066.44 | AC22: 1428.19 | AD22: 3256.28 | AE22: 30391.94 | AF22: =IF(tbl_FinancialData[[#This Row],[City]]="","Unknown",PROPER(TRIM(tbl_FinancialData[[#This Row],[City]]))) -> Kochi | AG22: =_xlfn.LET(_xlpm.city,LOWER(TRIM(tbl_FinancialData[[#This Row],[City]])),_xlpm.st,PROPER(TRIM(tbl_FinancialData[[#This Row],[State]])),IF(_xlpm.city="pune","Maharashtra",IF(_xlpm.city="jamshedpur","Jharkhand",IF(_xlpm.city="bhilai","Chhattisgarh",IF(_xlpm.city="mumbai","Maharashtra",_xlpm.st))))) -> Kerala | AH22: =_xlfn.LET(_xlpm.d,PROPER(TRIM(tbl_FinancialData[[#This Row],[Department]])),IF(_xlpm.d="It","IT",_xlpm.d)) -> Operations | AI22: =_xlfn.LET(_xlpm.pid,tbl_FinancialData[[#This Row],[Product ID]],_xlpm.n,PROPER(TRIM(tbl_FinancialData[[#This Row],[Product Name]])),IF(_xlpm.pid="P020","Document Scanner",IF(_xlpm.pid="P015","Network Router",SUBSTITUTE(SUBSTITUTE(_xlpm.n,"Crm","CRM"),"Ups","UPS")))) -> Printer | AJ22: =UPPER(TRIM(tbl_FinancialData[[#This Row],[Cost Center]])) -> CC-1005 | AL22: FINAL CLEANING VALIDATION
A23: TXN-00022 | B23: 45965 | C23: November | D23: ="Q"&INT(MOD(MONTH(B23)-4,12)/3)+1 -> Q3 | E23: ="FY"& (YEAR(B23)+(MONTH(B23)>=4)) -> FY2026 | F23: West | G23: India | H23: Maharashtra | I23: Nagpur | J23: Branch D | K23: Sales | L23: CC-1005 | M23: P010 | N23: Mouse | O23: Accessories | P23: Computer Accessories | Q23: 11029.55 | R23: 10569.26 | S23: 5334.7 | T23: 1375.11 | U23: 634.94 | V23: 917.11 | W23: 374.33 | X23: 8636.19 | Y23: 5694.85 | Z23: =Q23-X23 -> 2393.36 | AA23: =Z23/Q23 -> 0.21699525 | AB23: 460.28 | AC23: 551.48 | AD23: 1886.05 | AE23: 12364.12 | AF23: =IF(tbl_FinancialData[[#This Row],[City]]="","Unknown",PROPER(TRIM(tbl_FinancialData[[#This Row],[City]]))) -> Nagpur | AG23: =_xlfn.LET(_xlpm.city,LOWER(TRIM(tbl_FinancialData[[#This Row],[City]])),_xlpm.st,PROPER(TRIM(tbl_FinancialData[[#This Row],[State]])),IF(_xlpm.city="pune","Maharashtra",IF(_xlpm.city="jamshedpur","Jharkhand",IF(_xlpm.city="bhilai","Chhattisgarh",IF(_xlpm.city="mumbai","Maharashtra",_xlpm.st))))) -> Maharashtra | AH23: =_xlfn.LET(_xlpm.d,PROPER(TRIM(tbl_FinancialData[[#This Row],[Department]])),IF(_xlpm.d="It","IT",_xlpm.d)) -> Sales | AI23: =_xlfn.LET(_xlpm.pid,tbl_FinancialData[[#This Row],[Product ID]],_xlpm.n,PROPER(TRIM(tbl_FinancialData[[#This Row],[Product Name]])),IF(_xlpm.pid="P020","Document Scanner",IF(_xlpm.pid="P015","Network Router",SUBSTITUTE(SUBSTITUTE(_xlpm.n,"Crm","CRM"),"Ups","UPS")))) -> Mouse | AJ23: =UPPER(TRIM(tbl_FinancialData[[#This Row],[Cost Center]])) -> CC-1005
A24: TXN-00023 | B24: 46005 | C24: December | D24: ="Q"&INT(MOD(MONTH(B24)-4,12)/3)+1 -> Q3 | E24: ="FY"& (YEAR(B24)+(MONTH(B24)>=4)) -> FY2026 | F24: North | G24: India | H24: Uttar Pradesh | I24: Agra | J24: Branch D | K24: Operations | L24: CC-1002 | M24: P003 | N24: Printer | O24: Electronics | P24: Office Equipment | Q24: 49438.08 | R24: 51597.79 | S24: 34900.89 | T24: 3998.96 | U24: 4324.71 | V24: 5558.23 | W24: 833.16 | X24: 49615.95 | Y24: 14537.19 | Z24: =Q24-X24 -> -177.87 | AA24: =Z24/Q24 -> -0.0035978339 | AB24: -2159.7 | AC24: 0 | AD24: 2471.9 | AE24: 51909.99 | AF24: =IF(tbl_FinancialData[[#This Row],[City]]="","Unknown",PROPER(TRIM(tbl_FinancialData[[#This Row],[City]]))) -> Agra | AG24: =_xlfn.LET(_xlpm.city,LOWER(TRIM(tbl_FinancialData[[#This Row],[City]])),_xlpm.st,PROPER(TRIM(tbl_FinancialData[[#This Row],[State]])),IF(_xlpm.city="pune","Maharashtra",IF(_xlpm.city="jamshedpur","Jharkhand",IF(_xlpm.city="bhilai","Chhattisgarh",IF(_xlpm.city="mumbai","Maharashtra",_xlpm.st))))) -> Uttar Pradesh | AH24: =_xlfn.LET(_xlpm.d,PROPER(TRIM(tbl_FinancialData[[#This Row],[Department]])),IF(_xlpm.d="It","IT",_xlpm.d)) -> Operations | AI24: =_xlfn.LET(_xlpm.pid,tbl_FinancialData[[#This Row],[Product ID]],_xlpm.n,PROPER(TRIM(tbl_FinancialData[[#This Row],[Product Name]])),IF(_xlpm.pid="P020","Document Scanner",IF(_xlpm.pid="P015","Network Router",SUBSTITUTE(SUBSTITUTE(_xlpm.n,"Crm","CRM"),"Ups","UPS")))) -> Printer | AJ24: =UPPER(TRIM(tbl_FinancialData[[#This Row],[Cost Center]])) -> CC-1002 | AL24: Validation Check | AM24: Result | AN24: Status
A25: TXN-00024 | B25: 46000 | C25: December | D25: ="Q"&INT(MOD(MONTH(B25)-4,12)/3)+1 -> Q3 | E25: ="FY"& (YEAR(B25)+(MONTH(B25)>=4)) -> FY2026 | F25: North | G25: India | H25: Haryana | I25: Panipat | J25: Branch A | K25: Operations | L25: CC-1005 | M25: P010 | N25: Mouse | O25: Accessories | P25: Computer Accessories | Q25: 1711.26 | R25: 1650.61 | S25: 869.94 | T25: 180.95 | U25: 112.74 | V25: 188.58 | W25: 61.14 | X25: 1413.34 | Y25: 841.33 | Z25: =Q25-X25 -> 297.92 | AA25: =Z25/Q25 -> 0.17409394 | AB25: 60.65 | AC25: 136.9 | AD25: 188.92 | AE25: 1763.29 | AF25: =IF(tbl_FinancialData[[#This Row],[City]]="","Unknown",PROPER(TRIM(tbl_FinancialData[[#This Row],[City]]))) -> Panipat | AG25: =_xlfn.LET(_xlpm.city,LOWER(TRIM(tbl_FinancialData[[#This Row],[City]])),_xlpm.st,PROPER(TRIM(tbl_FinancialData[[#This Row],[State]])),IF(_xlpm.city="pune","Maharashtra",IF(_xlpm.city="jamshedpur","Jharkhand",IF(_xlpm.city="bhilai","Chhattisgarh",IF(_xlpm.city="mumbai","Maharashtra",_xlpm.st))))) -> Haryana | AH25: =_xlfn.LET(_xlpm.d,PROPER(TRIM(tbl_FinancialData[[#This Row],[Department]])),IF(_xlpm.d="It","IT",_xlpm.d)) -> Operations | AI25: =_xlfn.LET(_xlpm.pid,tbl_FinancialData[[#This Row],[Product ID]],_xlpm.n,PROPER(TRIM(tbl_FinancialData[[#This Row],[Product Name]])),IF(_xlpm.pid="P020","Document Scanner",IF(_xlpm.pid="P015","Network Router",SUBSTITUTE(SUBSTITUTE(_xlpm.n,"Crm","CRM"),"Ups","UPS")))) -> Mouse | AJ25: =UPPER(TRIM(tbl_FinancialData[[#This Row],[Cost Center]])) -> CC-1005 | AL25: Blank City | AM25: =COUNTBLANK(tbl_FinancialData[Clean City]) -> 0 | AN25: =IF(AM25=0,"PASS","CHECK") -> PASS
A26: TXN-00025 | B26: 46104 | C26: March | D26: ="Q"&INT(MOD(MONTH(B26)-4,12)/3)+1 -> Q4 | E26: ="FY"& (YEAR(B26)+(MONTH(B26)>=4)) -> FY2026 | F26: West | G26: India | H26: Rajasthan | I26: Udaipur | J26: Branch A | K26: Marketing | L26: CC-1004 | M26: P018 | N26: Projector | O26: Electronics | P26: Presentation | Q26: 32676.06 | R26: 37255.12 | S26: 20090.81 | T26: 2257.52 | U26: 2260.85 | V26: 3241.23 | W26: 599.22 | X26: 28449.63 | Y26: 12585.25 | Z26: =Q26-X26 -> 4226.43 | AA26: =Z26/Q26 -> 0.12934332 | AB26: -4579.06 | AC26: 980.28 | AD26: 3803.49 | AE26: 35499.27 | AF26: =IF(tbl_FinancialData[[#This Row],[City]]="","Unknown",PROPER(TRIM(tbl_FinancialData[[#This Row],[City]]))) -> Udaipur | AG26: =_xlfn.LET(_xlpm.city,LOWER(TRIM(tbl_FinancialData[[#This Row],[City]])),_xlpm.st,PROPER(TRIM(tbl_FinancialData[[#This Row],[State]])),IF(_xlpm.city="pune","Maharashtra",IF(_xlpm.city="jamshedpur","Jharkhand",IF(_xlpm.city="bhilai","Chhattisgarh",IF(_xlpm.city="mumbai","Maharashtra",_xlpm.st))))) -> Rajasthan | AH26: =_xlfn.LET(_xlpm.d,PROPER(TRIM(tbl_FinancialData[[#This Row],[Department]])),IF(_xlpm.d="It","IT",_xlpm.d)) -> Marketing | AI26: =_xlfn.LET(_xlpm.pid,tbl_FinancialData[[#This Row],[Product ID]],_xlpm.n,PROPER(TRIM(tbl_FinancialData[[#This Row],[Product Name]])),IF(_xlpm.pid="P020","Document Scanner",IF(_xlpm.pid="P015","Network Router",SUBSTITUTE(SUBSTITUTE(_xlpm.n,"Crm","CRM"),"Ups","UPS")))) -> Projector | AJ26: =UPPER(TRIM(tbl_FinancialData[[#This Row],[Cost Center]])) -> CC-1004 | AL26: Blank State | AM26: =COUNTBLANK(tbl_FinancialData[State]) -> 0 | AN26: =IF(AM26=0,"PASS","CHECK") -> PASS
A27: TXN-00026 | B27: 45831 | C27: June | D27: ="Q"&INT(MOD(MONTH(B27)-4,12)/3)+1 -> Q1 | E27: ="FY"& (YEAR(B27)+(MONTH(B27)>=4)) -> FY2026 | F27: West | G27: India | H27: Gujarat | I27: Ahmedabad | J27: Branch C | K27: Sales | L27: CC-1004 | M27: P012 | N27: Accounting Software | O27: Software | P27: Business Software | Q27: 34032.17 | R27: 33571.77 | S27: 24150.33 | T27: 3544.16 | U27: 1918.18 | V27: 2703.59 | W27: 439.52 | X27: 32755.78 | Y27: 9881.85 | Z27: =Q27-X27 -> 1276.39 | AA27: =Z27/Q27 -> 0.037505396 | AB27: 460.4 | AC27: 0 | AD27: 6125.79 | AE27: 40157.96 | AF27: =IF(tbl_FinancialData[[#This Row],[City]]="","Unknown",PROPER(TRIM(tbl_FinancialData[[#This Row],[City]]))) -> Ahmedabad | AG27: =_xlfn.LET(_xlpm.city,LOWER(TRIM(tbl_FinancialData[[#This Row],[City]])),_xlpm.st,PROPER(TRIM(tbl_FinancialData[[#This Row],[State]])),IF(_xlpm.city="pune","Maharashtra",IF(_xlpm.city="jamshedpur","Jharkhand",IF(_xlpm.city="bhilai","Chhattisgarh",IF(_xlpm.city="mumbai","Maharashtra",_xlpm.st))))) -> Gujarat | AH27: =_xlfn.LET(_xlpm.d,PROPER(TRIM(tbl_FinancialData[[#This Row],[Department]])),IF(_xlpm.d="It","IT",_xlpm.d)) -> Sales | AI27: =_xlfn.LET(_xlpm.pid,tbl_FinancialData[[#This Row],[Product ID]],_xlpm.n,PROPER(TRIM(tbl_FinancialData[[#This Row],[Product Name]])),IF(_xlpm.pid="P020","Document Scanner",IF(_xlpm.pid="P015","Network Router",SUBSTITUTE(SUBSTITUTE(_xlpm.n,"Crm","CRM"),"Ups","UPS")))) -> Accounting Software | AJ27: =UPPER(TRIM(tbl_FinancialData[[#This Row],[Cost Center]])) -> CC-1004 | AL27: Blank Department | AM27: =COUNTBLANK(tbl_FinancialData[Department]) -> 0 | AN27: =IF(AM27=0,"PASS","CHECK") -> PASS
A28: TXN-00027 | B28: 45800 | C28: May | D28: ="Q"&INT(MOD(MONTH(B28)-4,12)/3)+1 -> Q1 | E28: ="FY"& (YEAR(B28)+(MONTH(B28)>=4)) -> FY2026 | F28: West | G28: India | H28: Maharashtra | I28: Nagpur | J28: Branch A | K28: IT | L28: CC-1002 | M28: P007 | N28: Tablet | O28: Electronics | P28: Mobile | Q28: 50779.14 | R28: 55913.45 | S28: 31027.06 | T28: 5406.28 | U28: 4466.65 | V28: 4826.17 | W28: 1995.3 | X28: 47721.47 | Y28: 19752.08 | Z28: =Q28-X28 -> 3057.67 | AA28: =Z28/Q28 -> 0.06021508 | AB28: -5134.31 | AC28: 4062.33 | AD28: 8409.03 | AE28: 55125.84 | AF28: =IF(tbl_FinancialData[[#This Row],[City]]="","Unknown",PROPER(TRIM(tbl_FinancialData[[#This Row],[City]]))) -> Nagpur | AG28: =_xlfn.LET(_xlpm.city,LOWER(TRIM(tbl_FinancialData[[#This Row],[City]])),_xlpm.st,PROPER(TRIM(tbl_FinancialData[[#This Row],[State]])),IF(_xlpm.city="pune","Maharashtra",IF(_xlpm.city="jamshedpur","Jharkhand",IF(_xlpm.city="bhilai","Chhattisgarh",IF(_xlpm.city="mumbai","Maharashtra",_xlpm.st))))) -> Maharashtra | AH28: =_xlfn.LET(_xlpm.d,PROPER(TRIM(tbl_FinancialData[[#This Row],[Department]])),IF(_xlpm.d="It","IT",_xlpm.d)) -> IT | AI28: =_xlfn.LET(_xlpm.pid,tbl_FinancialData[[#This Row],[Product ID]],_xlpm.n,PROPER(TRIM(tbl_FinancialData[[#This Row],[Product Name]])),IF(_xlpm.pid="P020","Document Scanner",IF(_xlpm.pid="P015","Network Router",SUBSTITUTE(SUBSTITUTE(_xlpm.n,"Crm","CRM"),"Ups","UPS")))) -> Tablet | AJ28: =UPPER(TRIM(tbl_FinancialData[[#This Row],[Cost Center]])) -> CC-1002 | AL28: Blank Product Name | AM28: =COUNTBLANK(tbl_FinancialData[Product Name]) -> 0 | AN28: =IF(AM28=0,"PASS","CHECK") -> PASS
A29: TXN-00028 | B29: 45921 | C29: September | D29: ="Q"&INT(MOD(MONTH(B29)-4,12)/3)+1 -> Q2 | E29: ="FY"& (YEAR(B29)+(MONTH(B29)>=4)) -> FY2026 | F29: West | G29: India | H29: Gujarat | I29: Ahmedabad | J29: Branch B | K29: IT | L29: CC-1002 | M29: P005 | N29: Office Desk | O29: Furniture | P29: Office Furniture | Q29: 17169.71 | R29: 18103.6 | S29: 11798.22 | T29: 2067.73 | U29: 693.39 | V29: 1933.58 | W29: 527.39 | X29: 17020.3 | Y29: 5371.49 | Z29: =Q29-X29 -> 149.41 | AA29: =Z29/Q29 -> 0.0087019524 | AB29: -933.89 | AC29: 515.09 | AD29: 2997.83 | AE29: 19652.45 | AF29: =IF(tbl_FinancialData[[#This Row],[City]]="","Unknown",PROPER(TRIM(tbl_FinancialData[[#This Row],[City]]))) -> Ahmedabad | AG29: =_xlfn.LET(_xlpm.city,LOWER(TRIM(tbl_FinancialData[[#This Row],[City]])),_xlpm.st,PROPER(TRIM(tbl_FinancialData[[#This Row],[State]])),IF(_xlpm.city="pune","Maharashtra",IF(_xlpm.city="jamshedpur","Jharkhand",IF(_xlpm.city="bhilai","Chhattisgarh",IF(_xlpm.city="mumbai","Maharashtra",_xlpm.st))))) -> Gujarat | AH29: =_xlfn.LET(_xlpm.d,PROPER(TRIM(tbl_FinancialData[[#This Row],[Department]])),IF(_xlpm.d="It","IT",_xlpm.d)) -> IT | AI29: =_xlfn.LET(_xlpm.pid,tbl_FinancialData[[#This Row],[Product ID]],_xlpm.n,PROPER(TRIM(tbl_FinancialData[[#This Row],[Product Name]])),IF(_xlpm.pid="P020","Document Scanner",IF(_xlpm.pid="P015","Network Router",SUBSTITUTE(SUBSTITUTE(_xlpm.n,"Crm","CRM"),"Ups","UPS")))) -> Office Desk | AJ29: =UPPER(TRIM(tbl_FinancialData[[#This Row],[Cost Center]])) -> CC-1002 | AL29: Blank Cost Center | AM29: =COUNTBLANK(tbl_FinancialData[Cost Center]) -> 0 | AN29: =IF(AM29=0,"PASS","CHECK") -> PASS
